Workbook

Sheet Resumen
A1: Trabajo de grado 2026-2 - Propagadores con control de muestreo en DLHM
A3: Estudiante | B3: Camilo Rodriguez Londono | D3: COMO USAR ESTE ARCHIVO 1. La unica columna que se edita a diario es 'Estado' en la hoja Tareas (lista desplegable: Pendiente / En curso / Hecho / Bloqueado). 2. La hoja Cronograma calcula sola el avance de cada semana; no escribas en sus columnas de formula. 3. Usa la columna 'Notas' de la hoja Tareas para dejar constancia de bloqueos y decisiones. 4. Puedes agregar filas nuevas en Tareas hasta la fila 200 sin romper las formulas. SUPUESTO A VERIFICAR: se asume que la semana de receso es del 7 al 11 de septiembre. Las fechas institucionales confirmadas son semana 8 = 31 de agosto, semana 14 = 19 de octubre y entrega final = 30 de octubre; si el receso cae en otra semana, corre las fechas intermedias.
A4: Asesor principal | B4: Carlos Alejandro Trujillo Anaya, PhD
A5: Programa | B5: Ingenieria Fisica - Universidad EAFIT
A6: Modalidad de entrega | B6: Opcion 2 (grados de diciembre, sin mencion de honor)
A7: Entrega del informe final | B7: Viernes 30 de octubre de 2026 (semana 15)
A8: Defensa publica | B8: Hasta el viernes 20 de noviembre de 2026
A9: Ultima revision del plan | B9: Martes 1 de septiembre de 2026 (semana 8, dia 2)
A10: AVANCE GLOBAL
A11: Tareas totales | B11: =COUNTA(Tareas!$A$4:$A$200)
A12: Tareas completadas | B12: =COUNTIF(Tareas!$G$4:$G$200,"Hecho")
A13: Tareas en curso | B13: =COUNTIF(Tareas!$G$4:$G$200,"En curso")
A14: Tareas bloqueadas | B14: =COUNTIF(Tareas!$G$4:$G$200,"Bloqueado")
A15: Porcentaje completado | B15: =IFERROR(B12/B11,0)
A17: AVANCE POR FASE
A18: Fase | B18: Tareas | C18: Hechas
A19: Fase 1 - Implementacion | B19: =COUNTIF(Tareas!$C$4:$C$200,"F1") | C19: =COUNTIFS(Tareas!$C$4:$C$200,"F1",Tareas!$G$4:$G$200,"Hecho")
A20: Fase 2 - Calibracion numerica | B20: =COUNTIF(Tareas!$C$4:$C$200,"F2") | C20: =COUNTIFS(Tareas!$C$4:$C$200,"F2",Tareas!$G$4:$G$200,"Hecho")
A21: Fase 3 - Registro experimental | B21: =COUNTIF(Tareas!$C$4:$C$200,"F3") | C21: =COUNTIFS(Tareas!$C$4:$C$200,"F3",Tareas!$G$4:$G$200,"Hecho")
A22: Fase 4 - Comparacion y redaccion | B22: =COUNTIF(Tareas!$C$4:$C$200,"F4") | C22: =COUNTIFS(Tareas!$C$4:$C$200,"F4",Tareas!$G$4:$G$200,"Hecho")
A23: Hitos institucionales | B23: =COUNTIF(Tareas!$C$4:$C$200,"HITO") | C23: =COUNTIFS(Tareas!$C$4:$C$200,"HITO",Tareas!$G$4:$G$200,"Hecho")

Sheet Cronograma
A1: Cronograma semana a semana
A3: Semana | B3: Fechas | C3: Fase | D3: Foco de la semana | E3: Entregable de la semana | F3: Hito institucional | G3: Tareas | H3: Avance
A4: 4 | B4: 3 - 7 ago | C4: Fase 1 | D4: Reproducibilidad del codigo base | E4: Decision sobre el repositorio de Zhao | G4: =COUNTIF(Tareas!$B$4:$B$200,$A4) | H4: =IFERROR(COUNTIFS(Tareas!$B$4:$B$200,$A4,Tareas!$G$4:$G$200,"Hecho")/G4,0)
A5: 5 | B5: 10 - 14 ago | C5: Fase 1 | D5: FFT-ASM y BLAS bajo interfaz comun | E5: Dos propagadores verificados | G5: =COUNTIF(Tareas!$B$4:$B$200,$A5) | H5: =IFERROR(COUNTIFS(Tareas!$B$4:$B$200,$A5,Tareas!$G$4:$G$200,"Hecho")/G5,0)
A6: 6 | B6: 17 - 21 ago | C6: Fase 1 | D6: MPASM y verificacion analitica | E6: Objetivo 1 cerrado | G6: =COUNTIF(Tareas!$B$4:$B$200,$A6) | H6: =IFERROR(COUNTIFS(Tareas!$B$4:$B$200,$A6,Tareas!$G$4:$G$200,"Hecho")/G6,0)
A7: 7 | B7: 24 - 28 ago | C7: Fase 1 / 3 | D7: Montaje DLHM y parametros reales | E7: Hoja de parametros del montaje | G7: =COUNTIF(Tareas!$B$4:$B$200,$A7) | H7: =IFERROR(COUNTIFS(Tareas!$B$4:$B$200,$A7,Tareas!$G$4:$G$200,"Hecho")/G7,0)
A8: 8 | B8: 31 ago - 4 sep | C8: Hito | D8: Informe de avance 1 | E8: Exposicion (5 %) | F8: Informe de avance 1: 31 de agosto | G8: =COUNTIF(Tareas!$B$4:$B$200,$A8) | H8: =IFERROR(COUNTIFS(Tareas!$B$4:$B$200,$A8,Tareas!$G$4:$G$200,"Hecho")/G8,0)
A9: Receso | B9: 7 - 11 sep | C9: Receso | D9: Semana de receso (verificar calendario) | E9: Colchon del cronograma | G9: =COUNTIF(Tareas!$B$4:$B$200,$A9) | H9: =IFERROR(COUNTIFS(Tareas!$B$4:$B$200,$A9,Tareas!$G$4:$G$200,"Hecho")/G9,0)
A10: 9 | B10: 14 - 18 sep | C10: Fase 2 | D10: Iluminacion esferica en el esquema | E10: Pipeline DLHM validado en simulacion | G10: =COUNTIF(Tareas!$B$4:$B$200,$A10) | H10: =IFERROR(COUNTIFS(Tareas!$B$4:$B$200,$A10,Tareas!$G$4:$G$200,"Hecho")/G10,0)
A11: 10 | B11: 21 - 25 sep | C11: Fase 2 | D11: Barrido de parametros y mapas de error | E11: Objetivo 2 cerrado | G11: =COUNTIF(Tareas!$B$4:$B$200,$A11) | H11: =IFERROR(COUNTIFS(Tareas!$B$4:$B$200,$A11,Tareas!$G$4:$G$200,"Hecho")/G11,0)
A12: 11 | B12: 28 sep - 2 oct | C12: Fase 3 | D12: Registro experimental de hologramas | E12: Dataset documentado | G12: =COUNTIF(Tareas!$B$4:$B$200,$A12) | H12: =IFERROR(COUNTIFS(Tareas!$B$4:$B$200,$A12,Tareas!$G$4:$G$200,"Hecho")/G12,0)
A13: 12 | B13: 5 - 9 oct | C13: Fase 4 | D13: Reconstruccion y metricas comparativas | E13: Tabla comparativa completa | G13: =COUNTIF(Tareas!$B$4:$B$200,$A13) | H13: =IFERROR(COUNTIFS(Tareas!$B$4:$B$200,$A13,Tareas!$G$4:$G$200,"Hecho")/G13,0)
A14: 13 | B14: 12 - 16 oct | C14: Fase 4 | D14: Redaccion de resultados y analisis | E14: Borrador completo al asesor | G14: =COUNTIF(Tareas!$B$4:$B$200,$A14) | H14: =IFERROR(COUNTIFS(Tareas!$B$4:$B$200,$A14,Tareas!$G$4:$G$200,"Hecho")/G14,0)
A15: 14 | B15: 19 - 23 oct | C15: Hito | D15: Informe de avance 2 y correcciones | E15: Documento completo v1 | F15: Informe de avance 2: 19 de octubre | G15: =COUNTIF(Tareas!$B$4:$B$200,$A15) | H15: =IFERROR(COUNTIFS(Tareas!$B$4:$B$200,$A15,Tareas!$G$4:$G$200,"Hecho")/G15,0)
A16: 15 | B16: 26 - 30 oct | C16: Cierre | D16: Revision final y entrega | E16: Informe final + carta de aval | F16: ENTREGA FINAL: 30 de octubre | G16: =COUNTIF(Tareas!$B$4:$B$200,$A16) | H16: =IFERROR(COUNTIFS(Tareas!$B$4:$B$200,$A16,Tareas!$G$4:$G$200,"Hecho")/G16,0)

Sheet Tareas
A1: Lista de tareas - editar solo la columna Estado
A3: ID | B3: Semana | C3: Fase | D3: Tarea | E3: Entregable | F3: Prioridad | G3: Estado | H3: Fecha limite | I3: Notas
A4: 1 | B4: 4 | C4: F1 | D4: Consolidar correcciones y preguntas surgidas en la sustentacion | E4: Lista de ajustes acordados | F4: Alta | G4: Hecho | H4: 07/08/2026 | I4: CERRADA el 31/08. Los ajustes acordados en la sustentacion se responden en el material del avance 1. Estuvo abierta 24 dias mas alla de su fecha (07/08): es la tarea que mas tiempo llevo sin cerrar.
A5: 2 | B5: 4 | C5: F1 | D5: Clonar repositorio Figshare (Zhao 2020) y montar entorno Python | E5: Entorno reproducible | F5: Alta | G5: Hecho | H5: 07/08/2026
A6: 3 | B6: 4 | C6: F1 | D6: Reproducir la Figura 4 del paper con el codigo publicado | E6: Notebook de reproduccion | F6: Alta | G6: Hecho | H6: 07/08/2026 | I6: CERRADA el 23/08 (commit ea3a7a8). scripts/exactitud.py hace un solo barrido de 30 distancias -las siete de la tabla del paper mas una rejilla logaritmica entre ellas- y escribe resultados/exactitud/sam_vs_z.csv y sam_vs_z.png. La curva es la reproduccion de la Figura 4: MPASM entre 31 y 48 dB en todo el rango, FFT-ASM cayendo hasta -1.85 dB y BL-ASM degradandose y recuperandose cuando su mascara empieza a actuar. La vertical de la figura marca los 11.4 m a los que el radio 1/e del haz llena la ventana, que es donde FFT-ASM se desploma. Reproducida con CamposT, no con el codigo publicado: ese camino se cerro en la tarea 4 (port propio) y el contraste contra terceros vive en la tarea 58.
A7: 4 | B7: 4 | C7: F1 | D7: Documentar discrepancias y decidir si se reutiliza el codigo | E7: Decision go / no-go | F7: Alta | G7: Hecho | H7: 07/08/2026 | I7: Decidido: port propio a CamposT/propagadores.py en vez de reutilizar el codigo publicado. Se corrigio la Ec. (14): el codigo original usa A**2 * B donde el paper dice A**2 + B (ver kf_auto, formula='codigo' reproduce el bug).
A8: 5 | B8: 4 | C8: F1 | D8: Acordar con el asesor la agenda de reuniones semanales | E8: Agenda fijada | F8: Media | G8: Hecho | H8: 07/08/2026
A9: 6 | B9: 5 | C9: F1 | D9: Definir la interfaz comun del modulo (firma unica de propagacion) | E9: Especificacion de API | F9: Alta | G9: Hecho | H9: 14/08/2026 | I9: Hecha. La interfaz comun es pipeline.propagar(U0, delta, lamb, z, metodo, pad, device, dtype) -> (campo, info), uniforme para los tres metodos. Las funciones de bajo nivel conservan su retorno propio a proposito: mpasm devuelve Kf porque es un resultado del metodo, no un detalle de implementacion.
A10: 7 | B10: 5 | C10: F1 | D10: Implementar FFT-ASM | E10: Propagador funcional | F10: Alta | G10: Hecho | H10: 14/08/2026 | I10: CamposT/propagadores.py, fft_asm(). Revisado el 23/08 (commit c5fd678): aplica la transferencia in situ en vez de materializar H y multiplicar, que pedia dos arrays del tamano del plano de mas. Bit a bit identico, +4 % CPU y +7.6 % GPU. Corregido otra vez en la semana 7: ver tarea 66 (la rejilla de frecuencias estaba medio paso corrida en malla impar).
A11: 8 | B11: 5 | C11: F1 | D11: Implementar BLAS (espectro angular de banda limitada) | E11: Propagador funcional | F11: Alta | G11: Hecho | H11: 14/08/2026 | I11: CamposT/propagadores.py, blas() - Matsushima & Shimobaba (2009). Revisado el 23/08 (commit c5fd678): el limite de banda es un rectangulo centrado, asi que se anulan las cuatro bandas de fuera por rodajas en vez de construir H, dos meshgrid y una mascara. Bit a bit identico, +8.3 % CPU y +17.4 % GPU, y 1.6 GB menos de picos sobre una malla de 6000x8000. Corregido otra vez en la semana 7: ver tarea 66 (la misma rejilla medio paso corrida que fft_asm).
A12: 9 | B12: 5 | C12: F1 | D12: Tests unitarios: energia, caso z=0, reversibilidad | E12: Suite de tests | F12: Media | G12: Hecho | H12: 14/08/2026 | I12: tests/test_propagadores.py + tests/conftest.py. Cubre z=0, energia, reversibilidad, MPASM con Kf>1, paridad CPU/GPU, kf_auto y la funcion de transferencia. Validada por mutacion: 6 bugs inyectados, 6 detectados. Correr con: python -m pytest La suite fue creciendo con el paquete: 119 casos al crearse, 186 y 213 el 23/08 (retropropagacion y pipeline). AL 31/08 VA POR 299 CASOS EN VERDE en 56 s: los nuevos vienen de la rejilla centrada (16, tarea 66), el modo mixto, las fases de la retropropagacion, la nitidez, el pico de foco y la intensidad sin gamma. CERRADO el 01/09 lo de tests/mi_test.py (tarea 72): no costaba 12.2 s, COLGABA la recoleccion. Movido a scripts/, la suite pasa de 56 s a 38.29 s con los mismos 299 casos en verde.
A13: 10 | B13: 5 | C13: F1 | D13: Configurar repositorio git y estructura de paquete | E13: Repo inicializado | F13: Media | G13: Hecho | H13: 14/08/2026 | I13: Commit 3ef0cfa: paquete CamposT/ + scripts/ + referencia/ + resultados/. README con estructura y modo de ejecucion.
A14: 11 | B14: 6 | C14: F1 | D14: Implementar MPASM con parametros s y Kf explicitos | E14: Propagador funcional | F14: Alta | G14: Hecho | H14: 21/08/2026 | I14: Adelantada. CamposT/propagadores.py, mpasm() con s, Kf, r y mag explicitos y kf_auto() para el Kf automatico. Corregido despues, en la semana 6: ver tarea 63 (Kf a z < 0 y guardia de ventana de salida).
A15: 12 | B15: 6 | C15: F1 | D15: Implementar Rayleigh-Sommerfeld 1D como referencia numerica | E15: Referencia de verificacion | F15: Alta | G15: Hecho | H15: 21/08/2026 | I15: Hecha. CamposT/referencias.py, rs1_radial(): R-S I exacta reducida a 1-D por simetria circular (el paper dice que reduce el calculo 2-D a 1-D pero no como; es reescribir la integral en polares, sin aproximar). O(N_rho^2 N_phi) en vez de O(N^4): la fuerza bruta de pyLHM tardaria 1-2 h en la malla de la Tabla 1. Contrastada contra esa fuerza bruta y 19x mas exacta que ella (1.0e-3 frente a 1.9e-2 contra la analitica). No es paraxial, asi que su diferencia con gauss_analytic mide la paraxialidad. 11 tests, mutacion 8/8.
A16: 13 | B16: 6 | C16: F1 | D16: Verificacion contra propagacion analitica de haz gaussiano | E16: Curvas de error | F16: Alta | G16: Hecho | H16: 21/08/2026 | I16: CERRADA el 23/08 (commit ea3a7a8). Era el mismo entregable que la tarea 3 y sale de la misma figura: las curvas de error contra el gaussiano analitico, con SAM y no con RMS. Quedan las DOS referencias independientes -gauss_analytic, paraxial, y rs1_radial, no paraxial- mas la metrica del paper y su barrido graficado.
A17: 14 | B17: 6 | C17: F1 | D17: Implementar metrica SAM y generar curvas SAM vs z | E17: Graficas SAM | F17: Alta | G17: Hecho | H17: 21/08/2026 | I17: Hecha. CamposT/metricas.py, sam(). ERRATA ENCONTRADA en la Ec. (16): el denominador impreso es integral I_ref y tiene que ser integral I_ref^2. Con la impresa, un campo identico a su referencia da 0.365 dB en vez de infinito y el SAM queda bajo 2.5 dB para todo, o sea que el paper no habria podido generar su propia Figura 4. Segunda errata, tras el A^2*B de la Ec. (14). sam(formula='literal') reproduce la impresa. Al 23/08 su entregable -las graficas SAM- ya existe de verdad: resultados/exactitud/sam_vs_z.png (tarea 3). Y la metrica se endurecio (commit 61e7e1a) contra tres casos degenerados que devolvian un numero creible: un campo nulo daba +inf, o sea el mejor valor posible, porque la Ec. (15) queda 0/0 y la rama del residuo no miraba el numerador; una referencia nula daba NaN con un aviso de NumPy; y dos mallas distintas se difundian en silencio, que es facil de encontrarse porque rs1_radial devuelve perfiles radiales. 15 tests.
A18: 15 | B18: 6 | C18: F1 | D18: Redactar seccion de metodologia: implementacion (Obj. 1) | E18: Borrador de seccion | F18: Media | G18: Pendiente | H18: 21/08/2026 | I18: SIN EMPEZAR el 31/08, diez dias despues de vencer. Las diapositivas del avance 1 salieron sin ella. El material esta escrito pero disperso -el README, los docstrings del paquete y las notas de este cronograma-: falta pasarlo a prosa de tesis, y a partir de hoy compite con la Fase 2. Es la primera deuda de escritura del proyecto. AL 01/09 SIGUE SIN EMPEZAR y queda fuera del foco de la semana 8 y del receso, que se dedican a la tarea 17, a la Fase 2 (24-26) y a la limpieza del repo. Se arrastra a la semana 9, donde ya compite con F2. Es la segunda vez que se aplaza.
A19: 16 | B19: 7 | C19: F3 | D19: Sesion de familiarizacion con el montaje DLHM | E19: Bitacora de laboratorio | F19: Alta | G19: Hecho | H19: 28/08/2026 | I19: Hecha en la semana 7. Queda pendiente lo que tenia que salir de ella: los parametros reales del montaje (tarea 17).
A20: 17 | B20: 7 | C20: F3 | D20: Levantar parametros reales: lambda, pitch, sensor, L, z, NA | E20: Hoja de parametros | F20: Alta | G20: En curso | H20: 28/08/2026 | I20: VENCIDA el 28/08 y abierta al 31/08. Es la dependencia mas critica del cronograma: la Fase 2 arranca el 14/09 -dos semanas, con el receso de por medio- y sin lambda, pitch, sensor, L, z y NA reales el barrido de la tarea 30 se corre sobre valores inventados y hay que repetirlo. El acceso al montaje ya no es el bloqueo: la sesion de familiarizacion (tarea 16) y la reserva de laboratorio (tarea 18) estan hechas. AL 01/09 ES EL FOCO DE LA SEMANA 8: quedan cuatro dias habiles (1-4 sep) antes del receso, y despues del receso solo queda la semana del 14/09, que es cuando arranca la Fase 2 que depende de estos numeros. Al 01/09 su entregable esta PREPARADO Y VACIO (tarea 73): docs/hoja_parametros_montaje.md es el checklist que se lleva al laboratorio y CamposT/montaje.py el destino de los numeros. Faltan los 15 valores; cualquier cuenta que use uno de ellos falla en el acto en vez de propagar un valor inventado. CONFIRMADO el 01/09 que hay acceso al montaje esta misma semana, asi que la tarea deja de depender de la reserva de las semanas 9 a 11. EN CURSO desde el 20/09 (commit 4e0927c0e): montaje.py tiene ya lambda, pinhole, los dos pasos de pixel y L medidos, 5 de los 15 parametros. Quedan 10 pendientes.
... A25: 22 | B25: 8 | C25: HITO | D25: Registrar retroalimentacion y ajustar el plan | E25: Plan actualizado | F25: Media | G25: Hecho | H25: 31/08/2026 | I25: CERRADA el 01/09. La retroalimentacion del avance 1 no trajo ajustes al cronograma, asi que el plan sigue vigente sin cambios. Lo que decide el arranque de la Fase 2 no es esta retroalimentacion sino la tarea 17, que sigue vencida.
A26: 23 | B26: Receso | C26: BUF | D26: Semana de receso: recuperar tareas atrasadas o lectura pendiente | E26: Colchon del cronograma | F26: Baja | G26: Pendiente | H26: 11/09/2026
A27: 24 | B27: 9 | C27: F2 | D27: Formular la adaptacion a iluminacion esferica divergente | E27: Desarrollo teorico | F27: Alta | G27: Hecho | H27: 25/09/2026 | I27: Adelantada. figura_escenario.py (commit c6963d1) fija la primitiva: la lente f = -300 mm de la Tabla 1, aplicada sobre la cintura, deja el haz con R = 300 mm y la cintura intacta, o sea un pinhole virtual. Se modela el frente esferico divergente, no la lente. Falta pasar de la figura al desarrollo escrito. Reunion con el asesor el 08/09 (docs/reunion_asesor.pdf): la fecha limite se corrio al 25/09 (fin de semana 10). CERRADA el 22/09: docs/tarea24_mpasm_onda_esferica.pdf es el desarrollo escrito que faltaba, sobre la onda esferica en MPASM.
A28: 25 | B28: 9 | C28: F2 | D28: Implementar compensacion de fase y magnificacion geometrica | E28: Codigo funcional | F28: Alta | G28: Hecho | H28: 18/09/2026 | I28: La magnificacion geometrica ya existe: parametro mag de mpasm (r1, r2 de las Ecs. (7)-(8)), verificado en figura_escenario.py con malla de salida 6x. Falta la compensacion de fase de la iluminacion divergente. CERRADA el 27/09 con la tarea 78 (commit 17b6e2f510), fuera de su fecha del 18/09. La compensacion de fase de la iluminacion divergente es la esferica EXACTA e^{ikr}/r, en los dos sentidos y sin aproximacion paraxial: al reconstruir se multiplica por la de la fuente vista en el sensor (R = L) y se divide por la vista en la muestra (R = z); su parte parabolica va dentro de las matrices de la DFT del MPASM y el residuo punto a punto. La magnificacion geometrica M = L/z es exacta (proyeccion central entre planos paralelos) y entra como la malla de la muestra, delta*z/L, sin reescalar nada. Verificado contra Rayleigh-Sommerfeld directo: 3.6e-6 de error relativo hasta 12.4 grados.
A29: 26 | B29: 9 | C29: F2 | D29: Montar el pipeline de reconstruccion DLHM con los 4 propagadores | E29: Pipeline unificado | F29: Alta | G29: En curso | H29: 18/09/2026 | I29: Empezada por su mitad general: CamposT/retropropagacion.py (tarea 64) ya reconstruye sobre un barrido de z con los tres propagadores del paquete, pero asume iluminacion colimada. Al 31/08 se suma scripts/retro_holograma.py (tarea 67), que retropropaga un holograma ya registrado llamando a pipeline.propagar(), con los tres propagadores sobre el mismo dato y la misma z. Falta lo especifico de DLHM: la fuente puntual divergente (magnificacion M = L/z y distancia efectiva, tarea 24) y el cuarto propagador.
A30: 27 | B30: 9 | C30: F2 | D30: Validar con holograma simulado de muestra sintetica | E30: Reconstruccion simulada | F30: Alta | G30: Hecho | H30: 18/09/2026 | I30: ADELANTADA (era semana 9). Validacion de extremo a extremo sobre DLHM-model: holograma simulado con verdad-terreno conocida, retropropagado con MPASM. La fase reconstruida a la distancia nominal devuelve el target con los grupos de barras USAF y sus numeros legibles, sin ajustar parametros. Dos lecciones: el caso cae FUERA del rango de FFT-ASM (z_lim = 6.6 mm frente a z = 24 mm), y el criterio de autofoco depende del tipo de objeto (en fase hay que MINIMIZAR la varianza de amplitud, no maximizar nitidez). Falta versionarlo como scripts/reconstruccion_dlhm.py. Al 23/08 la maquinaria de retropropagacion ya esta versionada (tarea 64), asi que lo que queda es rehacer esa validacion llamando al paquete en vez del script suelto. CERRADA el 27/09 con la tarea 78 (commit 17b6e2f510), fuera de su fecha del 18/09. La validacion ya llama al paquete (CamposT.dlhm) y queda versionada como scripts/verif_dlhm_esferico.py, no como scripts/reconstruccion_dlhm.py. Hologramas simulados con la ida exacta (3.6e-6 contra RS directo) de dos muestras sinteticas con verdad-terreno: un mosaico de detalle de ~1.25 um, reconstruido con corr 0.969 en la ventana entera del sensor de 3000 px (1.0000 hasta 3 grados), y el BenchmarkTarget de DLHM-model a z = 3 mm, del que un barrido por nitidez sobre el holograma de INTENSIDAD recupera z = 3.0005 mm sin conocer el objeto. La imagen gemela sigue sin suprimirse (corr 0.95 en el centro con intensidad, 1.000 con el campo complejo).
A31: 28 | B31: 9 | C31: F2 | D31: Redactar seccion: propagacion bajo iluminacion esferica | E31: Borrador de seccion | F31: Media | G31: Pendiente | H31: 18/09/2026
A32: 29 | B32: 10 | C32: F2 | D32: Definir la malla del barrido de parametros (z, NA, s, Kf) | E32: Diseno del barrido | F32: Alta | G32: Pendiente | H32: 25/09/2026
A33: 30 | B33: 10 | C33: F2 | D33: Ejecutar el barrido y generar los mapas de error | E33: Mapas de validez | F33: Alta | G33: Pendiente | H33: 25/09/2026
A34: 31 | B34: 10 | C34: F2 | D34: Derivar el criterio operativo de seleccion de s y Kf | E34: Criterio documentado | F34: Alta | G34: En curso | H34: 25/09/2026 | I34: Primer criterio duro ya derivado, y metido en el codigo en vez de solo documentado: r*mag <= s*Kf (mpasm._comprobar_ventana, tarea 63). Sale de que el espectro, muestreado cada 1/(s*N*delta*Kf), describe un campo que se repite cada s*N*delta*Kf, mientras la malla de salida abarca r*N*delta*mag. Falta el criterio de eleccion de s y Kf frente a z y NA, que es lo que dara el barrido de la tarea 30.
A35: 32 | B35: 10 | C35: F2 | D35: Contrastar MPASM y CZT termino a termino | E35: Nota tecnica | F35: Media | G35: En curso | H35: 25/09/2026 | I35: Contraste parcial hecho: scripts/contraste_referencias.py compara CamposT contra pyDHM (angularSpectrum y bluestein/CZT). fft_asm coincide con pyDHM.angularSpectrum a 1e-8. Falta el contraste termino a termino MPASM vs CZT. Se suma scripts/retro_fft_angular.py: la ida y vuelta con el angularSpectrum de pyDHM tal cual, en una sola pieza y sin importar CamposT, como contraste independiente del paquete. Deja medidos dos defectos del original: dfx y dfy cruzados (irrelevante en malla cuadrada, 2.95e-1 de error contra el gaussiano analitico en malla rectangular) y las evanescentes dejadas decaer, que al RETROPROPAGAR crecen en vez de decaer. Al 23/08 se suma retro_mpasm.py (tarea 65), que contrasta MPASM contra el original de Zhao termino a termino y da 0.000e+00 en doble precision. No cierra esta tarea: lo que sigue pendiente es el contraste contra la CZT de pyDHM, que es otro metodo y no otra implementacion del mismo.
A36: 33 | B36: 10 | C36: F2 | D36: Redactar seccion: calibracion numerica (Obj. 2) | E36: Borrador de seccion | F36: Media | G36: Pendiente | H36: 25/09/2026
A37: 34 | B37: 11 | C37: F3 | D37: Alineacion del montaje y verificacion de estabilidad | E37: Montaje alineado | F37: Alta | G37: Pendiente | H37: 02/10/2026
A38: 35 | B38: 11 | C38: F3 | D38: Registro de hologramas del target USAF 1951 a dos o mas magnificaciones | E38: Hologramas USAF | F38: Alta | G38: Pendiente | H38: 02/10/2026
A39: 36 | B39: 11 | C39: F3 | D39: Registro de muestra micrometrica o biologica | E39: Hologramas de muestra | F39: Media | G39: Pendiente | H39: 02/10/2026
A40: 37 | B40: 11 | C40: F3 | D40: Capturar referencias sin muestra y ruido de fondo | E40: Imagenes de referencia | F40: Alta | G40: Pendiente | H40: 02/10/2026
A41: 38 | B41: 11 | C41: F3 | D41: Organizar el dataset con metadatos y respaldo | E41: Dataset documentado | F41: Alta | G41: Pendiente | H41: 02/10/2026
A42: 39 | B42: 12 | C42: F4 | D42: Reconstruir todo el dataset con los 4 propagadores | E42: Reconstrucciones completas | F42: Alta | G42: Pendiente | H42: 09/10/2026
A43: 40 | B43: 12 | C43: F4 | D43: Medir resolucion lateral efectiva sobre el target USAF | E43: Tabla de resolucion | F43: Alta | G43: Pendiente | H43: 09/10/2026
A44: 41 | B44: 12 | C44: F4 | D44: Medir contraste, relacion senal-ruido y tiempo de computo | E44: Tabla de metricas | F44: Alta | G44: Pendiente | H44: 09/10/2026
A45: 42 | B45: 12 | C45: F4 | D45: Consolidar la tabla comparativa de resultados | E45: Tabla final | F45: Alta | G45: Pendiente | H45: 09/10/2026
...

Sheet Hitos
A1: Fechas institucionales confirmadas (Directrices 2026-2)
A3: Fecha | B3: Semana | C3: Actividad | D3: Peso en la nota
A4: 27 de julio de 2026 | B4: 3 | C4: Anteproyecto - documento escrito | D4: 10 % (con sustentacion)
A5: 3 de agosto de 2026 | B5: 4 | C5: Anteproyecto - sustentacion oral | D5: 10 % (con documento)
A6: 31 de agosto de 2026 | B6: 8 | C6: Exposicion informe de avance 1 | D6: 5 %
A7: 19 de octubre de 2026 | B7: 14 | C7: Exposicion informe de avance 2 | D7: 5 %
A8: 30 de octubre de 2026 | B8: 15 | C8: Limite de entrega del informe final con carta de aval | D8: -
A9: Hasta el 20 de noviembre de 2026 | B9: 18 | C9: Defensa o presentacion publica ante jurados | D9: 45 %
A10: Hasta el 20 de noviembre de 2026 | B10: 18 | C10: Desarrollo del trabajo y sustentacion (asesor) | D10: 35 %
A11: 9 y 10 de diciembre de 2026 | B11: - | C11: Ceremonia de grados | D11: -
A13: Nota: la Opcion 1 (con opcion a mencion de honor) exigiria entregar el informe final el 13 de octubre (semana 13) y defender antes del 6 de noviembre. Este cronograma sigue la Opcion 2.
